<mujoco model="b1z1_description">
  <compiler angle="radian" meshdir="../meshes/"/>
  <asset>
    <mesh name="trunk" file="trunk.stl"/>
    <mesh name="hip" file="hip.stl"/>
    <mesh name="thigh_mirror" file="thigh_mirror.stl"/>
    <mesh name="calf" file="calf.stl"/>
    <mesh name="thigh" file="thigh.stl"/>
    <mesh name="z1_Link00" file="z1_Link00.stl"/>
    <mesh name="z1_Link01" file="z1_Link01.stl"/>
    <mesh name="z1_Link02" file="z1_Link02.stl"/>
    <mesh name="z1_Link03" file="z1_Link03.stl"/>
    <mesh name="z1_Link04" file="z1_Link04.stl"/>
    <mesh name="z1_Link05" file="z1_Link05.stl"/>
    <mesh name="z1_Link06" file="z1_Link06.stl"/>
  </asset>
  <worldbody>
    <body name="base" pos="0 0 1.0">
      <joint name="floating_base" type="free"/>
      <geom size="0.0005 0.0005 0.0005" type="box" contype="0" conaffinity="0" group="1" density="0"/>
      <geom type="mesh" contype="0" conaffinity="0" group="1" density="0" rgba="0.913725 0.913725 0.847059 1" mesh="trunk"/>
      <geom size="0.35 0.075 0.11" type="box" rgba="0.913725 0.913725 0.847059 0"/>
      <geom size="0.0005 0.0005 0.0005" type="box" contype="0" conaffinity="0" group="1" density="0" rgba="0.8 0 0 0"/>
      <geom size="0.05 0.01" pos="0.1955 -0.072 0" quat="0.707107 0 0.707107 0" type="cylinder" contype="0" conaffinity="0" group="1" density="0" rgba="0 0 0 0"/>
      <geom size="0.05 0.01" pos="0.1955 0.072 0" quat="0.707107 0 0.707107 0" type="cylinder" contype="0" conaffinity="0" group="1" density="0" rgba="0 0 0 0"/>
      <geom size="0.05 0.01" pos="-0.1955 -0.072 0" quat="0.707107 0 0.707107 0" type="cylinder" contype="0" conaffinity="0" group="1" density="0" rgba="0 0 0 0"/>
      <geom size="0.05 0.01" pos="-0.1955 0.072 0" quat="0.707107 0 0.707107 0" type="cylinder" contype="0" conaffinity="0" group="1" density="0" rgba="0 0 0 0"/>
      <geom type="mesh" contype="0" conaffinity="0" group="1" density="0" mesh="z1_Link00"/>
      <geom size="0.0325 0.0255" pos="0 0 0.0255" type="cylinder"/>
      <body name="FR_hip" pos="0.3455 -0.072 0">
        <inertial pos="-0.018016 -0.00971213 9.67456e-05" quat="0.514022 0.512801 0.485949 0.486488" mass="2.366" diaginertia="0.00980696 0.00664332 0.0045362"/>
        <joint name="FR_hip_joint" pos="0 0 0" axis="1 0 0" range="-0.75 0.75"/>
        <geom quat="0 1 0 0" type="mesh" contype="0" conaffinity="0" group="1" density="0" rgba="0.913725 0.913725 0.847059 1" mesh="hip"/>
        <geom size="0.05 0.01" pos="0 -0.00935 0" quat="0.707107 0.707107 0 0" type="cylinder" contype="0" conaffinity="0" group="1" density="0" rgba="0 0 0 0"/>
        <body name="FR_thigh" pos="0 -0.12675 0">
          <inertial pos="-0.000220117 0.0301731 -0.0507383" quat="0.736596 -0.0378368 0.076521 0.670924" mass="4.2" diaginertia="0.0487177 0.0459334 0.00814802"/>
          <joint name="FR_thigh_joint" pos="0 0 0" axis="0 1 0" range="-1 3.5"/>
          <geom type="mesh" contype="0" conaffinity="0" group="1" density="0" rgba="0.913725 0.913725 0.847059 1" mesh="thigh_mirror"/>
          <geom size="0.175 0.025 0.04" pos="0 0 -0.175" quat="0.707107 0 0.707107 0" type="box" rgba="0.913725 0.913725 0.847059 0"/>
          <geom size="0.05 0.01" pos="0 0.0519 0" quat="0.707107 0.707107 0 0" type="cylinder" contype="0" conaffinity="0" group="1" density="0" rgba="0 0 0 0"/>
          <body name="FR_calf" pos="0 0 -0.35">
            <inertial pos="0.0049483 0 -0.210919" quat="0.707231 -0.00481122 -0.00483372 0.70695" mass="0.907" diaginertia="0.0162164 0.0160695 0.000406131"/>
            <joint name="FR_calf_joint" pos="0 0 0" axis="0 1 0" range="-2.6 -0.6"/>
            <geom type="mesh" contype="0" conaffinity="0" group="1" density="0" rgba="0 0 0 1" mesh="calf"/>
            <geom size="0.175 0.02 0.025" pos="0 0 -0.175" quat="0.707107 0 0.707107 0" type="box" rgba="0 0 0 0"/>
            <geom size="0.03" pos="0 0 -0.35" contype="0" conaffinity="0" group="1" density="0" rgba="0 0 0 1"/>
            <geom size="0.04" pos="0 0 -0.35" rgba="0 0 0 1"/>
          </body>
        </body>
      </body>
      <body name="FL_hip" pos="0.3455 0.072 0">
        <inertial pos="-0.018016 0.00971213 9.67456e-05" quat="0.486488 0.485949 0.512801 0.514022" mass="2.366" diaginertia="0.00980696 0.00664332 0.0045362"/>
        <joint name="FL_hip_joint" pos="0 0 0" axis="1 0 0" range="-0.75 0.75"/>
        <geom type="mesh" contype="0" conaffinity="0" group="1" density="0" rgba="0.913725 0.913725 0.847059 1" mesh="hip"/>
        <geom size="0.05 0.01" pos="0 0.00935 0" quat="0.707107 0.707107 0 0" type="cylinder" contype="0" conaffinity="0" group="1" density="0" rgba="0 0 0 0"/>
        <body name="FL_thigh" pos="0 0.12675 0">
          <inertial pos="-0.000220117 -0.0301731 -0.0507383" quat="0.670924 0.076521 -0.0378368 0.736596" mass="4.2" diaginertia="0.0487177 0.0459334 0.00814802"/>
          <joint name="FL_thigh_joint" pos="0 0 0" axis="0 1 0" range="-1 3.5"/>
          <geom type="mesh" contype="0" conaffinity="0" group="1" density="0" rgba="0.913725 0.913725 0.847059 1" mesh="thigh"/>
          <geom size="0.175 0.025 0.04" pos="0 0 -0.175" quat="0.707107 0 0.707107 0" type="box" rgba="0.913725 0.913725 0.847059 0"/>
          <geom size="0.05 0.01" pos="0 -0.0519 0" quat="0.707107 0.707107 0 0" type="cylinder" contype="0" conaffinity="0" group="1" density="0" rgba="0 0 0 0"/>
          <body name="FL_calf" pos="0 0 -0.35">
            <inertial pos="0.0049483 0 -0.210919" quat="0.707231 -0.00481122 -0.00483372 0.70695" mass="0.907" diaginertia="0.0162164 0.0160695 0.000406131"/>
            <joint name="FL_calf_joint" pos="0 0 0" axis="0 1 0" range="-2.6 -0.6"/>
            <geom type="mesh" contype="0" conaffinity="0" group="1" density="0" rgba="0 0 0 1" mesh="calf"/>
            <geom size="0.175 0.02 0.025" pos="0 0 -0.175" quat="0.707107 0 0.707107 0" type="box" rgba="0 0 0 0"/>
            <geom size="0.03" pos="0 0 -0.35" contype="0" conaffinity="0" group="1" density="0" rgba="0 0 0 1"/>
            <geom size="0.04" pos="0 0 -0.35" rgba="0 0 0 1"/>
          </body>
        </body>
      </body>
      <body name="RR_hip" pos="-0.3455 -0.072 0">
        <inertial pos="0.018016 -0.00971213 9.67456e-05" quat="0.485949 0.486488 0.514022 0.512801" mass="2.366" diaginertia="0.00980696 0.00664332 0.0045362"/>
        <joint name="RR_hip_joint" pos="0 0 0" axis="1 0 0" range="-0.75 0.75"/>
        <geom quat="0 0 0 -1" type="mesh" contype="0" conaffinity="0" group="1" density="0" rgba="0.913725 0.913725 0.847059 1" mesh="hip"/>
        <geom size="0.05 0.01" pos="0 -0.00935 0" quat="0.707107 0.707107 0 0" type="cylinder" contype="0" conaffinity="0" group="1" density="0" rgba="0 0 0 0"/>
        <body name="RR_thigh" pos="0 -0.12675 0">
          <inertial pos="-0.000220117 0.0301731 -0.0507383" quat="0.736596 -0.0378368 0.076521 0.670924" mass="4.2" diaginertia="0.0487177 0.0459334 0.00814802"/>
          <joint name="RR_thigh_joint" pos="0 0 0" axis="0 1 0" range="-1 3.5"/>
          <geom type="mesh" contype="0" conaffinity="0" group="1" density="0" rgba="0.913725 0.913725 0.847059 1" mesh="thigh_mirror"/>
          <geom size="0.175 0.025 0.04" pos="0 0 -0.175" quat="0.707107 0 0.707107 0" type="box" rgba="0.913725 0.913725 0.847059 0"/>
          <geom size="0.05 0.01" pos="0 0.0519 0" quat="0.707107 0.707107 0 0" type="cylinder" contype="0" conaffinity="0" group="1" density="0" rgba="0 0 0 0"/>
          <body name="RR_calf" pos="0 0 -0.35">
            <inertial pos="0.0049483 0 -0.210919" quat="0.707231 -0.00481122 -0.00483372 0.70695" mass="0.907" diaginertia="0.0162164 0.0160695 0.000406131"/>
            <joint name="RR_calf_joint" pos="0 0 0" axis="0 1 0" range="-2.6 -0.6"/>
            <geom type="mesh" contype="0" conaffinity="0" group="1" density="0" rgba="0 0 0 1" mesh="calf"/>
            <geom size="0.175 0.02 0.025" pos="0 0 -0.175" quat="0.707107 0 0.707107 0" type="box" rgba="0 0 0 0"/>
            <geom size="0.03" pos="0 0 -0.35" contype="0" conaffinity="0" group="1" density="0" rgba="0 0 0 1"/>
            <geom size="0.04" pos="0 0 -0.35" rgba="0 0 0 1"/>
          </body>
        </body>
      </body>
      <body name="RL_hip" pos="-0.3455 0.072 0">
        <inertial pos="0.018016 0.00971213 9.67456e-05" quat="0.512801 0.514022 0.486488 0.485949" mass="2.366" diaginertia="0.00980696 0.00664332 0.0045362"/>
        <joint name="RL_hip_joint" pos="0 0 0" axis="1 0 0" range="-0.75 0.75"/>
        <geom quat="0 0 1 0" type="mesh" contype="0" conaffinity="0" group="1" density="0" rgba="0.913725 0.913725 0.847059 1" mesh="hip"/>
        <geom size="0.05 0.01" pos="0 0.00935 0" quat="0.707107 0.707107 0 0" type="cylinder" contype="0" conaffinity="0" group="1" density="0" rgba="0 0 0 0"/>
        <body name="RL_thigh" pos="0 0.12675 0">
          <inertial pos="-0.000220117 -0.0301731 -0.0507383" quat="0.670924 0.076521 -0.0378368 0.736596" mass="4.2" diaginertia="0.0487177 0.0459334 0.00814802"/>
          <joint name="RL_thigh_joint" pos="0 0 0" axis="0 1 0" range="-1 3.5"/>
          <geom type="mesh" contype="0" conaffinity="0" group="1" density="0" rgba="0.913725 0.913725 0.847059 1" mesh="thigh"/>
          <geom size="0.175 0.025 0.04" pos="0 0 -0.175" quat="0.707107 0 0.707107 0" type="box" rgba="0.913725 0.913725 0.847059 0"/>
          <geom size="0.05 0.01" pos="0 -0.0519 0" quat="0.707107 0.707107 0 0" type="cylinder" contype="0" conaffinity="0" group="1" density="0" rgba="0 0 0 0"/>
          <body name="RL_calf" pos="0 0 -0.35">
            <inertial pos="0.0049483 0 -0.210919" quat="0.707231 -0.00481122 -0.00483372 0.70695" mass="0.907" diaginertia="0.0162164 0.0160695 0.000406131"/>
            <joint name="RL_calf_joint" pos="0 0 0" axis="0 1 0" range="-2.6 -0.6"/>
            <geom type="mesh" contype="0" conaffinity="0" group="1" density="0" rgba="0 0 0 1" mesh="calf"/>
            <geom size="0.175 0.02 0.025" pos="0 0 -0.175" quat="0.707107 0 0.707107 0" type="box" rgba="0 0 0 0"/>
            <geom size="0.03" pos="0 0 -0.35" contype="0" conaffinity="0" group="1" density="0" rgba="0 0 0 1"/>
            <geom size="0.04" pos="0 0 -0.35" rgba="0 0 0 1"/>
          </body>
        </body>
      </body>
      <body name="link01" pos="0 0 0.0585">
        <inertial pos="2.47e-06 -0.00025198 0.0231717" quat="0.708578 0.705633 0.000281462 -0.000355927" mass="0.673326" diaginertia="0.00128328 0.000839362 0.000719308"/>
        <joint name="joint1" pos="0 0 0" axis="0 0 1" range="-2.61799 2.61799" damping="1" frictionloss="1"/>
        <geom type="mesh" contype="0" conaffinity="0" group="1" density="0" mesh="z1_Link01"/>
        <body name="link02" pos="0 0 0.045">
          <inertial pos="-0.110126 0.00240029 0.00158266" quat="0.00748058 0.707092 -0.0114473 0.70699" mass="1.19132" diaginertia="0.0246612 0.0243113 0.00100468"/>
          <joint name="joint2" pos="0 0 0" axis="0 1 0" range="0 2.96706" damping="2" frictionloss="2"/>
          <geom type="mesh" contype="0" conaffinity="0" group="1" density="0" mesh="z1_Link02"/>
          <geom size="0.0325 0.051" quat="0.707107 0.707107 0 0" type="cylinder"/>
          <geom size="0.0225 0.1175" pos="-0.1625 0 0" quat="0.707107 0 0.707107 0" type="cylinder"/>
          <geom size="0.0325 0.0255" pos="-0.35 0 0" quat="0.707107 0.707107 0 0" type="cylinder"/>
          <body name="link03" pos="-0.35 0 0">
            <inertial pos="0.106092 -0.00541815 0.0347638" quat="0.540557 0.443575 0.426319 0.573839" mass="0.839409" diaginertia="0.00954365 0.00938711 0.000558432"/>
            <joint name="joint3" pos="0 0 0" axis="0 1 0" range="-2.87979 0" damping="1" frictionloss="1"/>
            <geom type="mesh" contype="0" conaffinity="0" group="1" density="0" mesh="z1_Link03"/>
            <geom size="0.02 0.058" pos="0.128 0 0.055" quat="0.707107 0 0.707107 0" type="cylinder"/>
            <geom size="0.0325 0.0295" pos="0.2205 0 0.055" quat="0.5 -0.5 0.5 0.5" type="cylinder"/>
            <body name="link04" pos="0.218 0 0.057">
              <inertial pos="0.0436668 0.00364738 -0.00170192" quat="0.0390835 0.726445 -0.0526787 0.684087" mass="0.564046" diaginertia="0.000981656 0.00094053 0.000302655"/>
              <joint name="joint4" pos="0 0 0" axis="0 1 0" range="-1.51844 1.51844" damping="1" frictionloss="1"/>
              <geom type="mesh" contype="0" conaffinity="0" group="1" density="0" mesh="z1_Link04"/>
              <geom size="0.0325 0.0335" pos="0.072 0 0" type="cylinder"/>
              <body name="link05" pos="0.07 0 0">
                <inertial pos="0.0312153 0 0.00646316" quat="0.462205 0.535209 0.53785 0.45895" mass="0.389385" diaginertia="0.000558961 0.000547317 0.000167332"/>
                <joint name="joint5" pos="0 0 0" axis="0 0 1" range="-1.3439 1.3439" damping="1" frictionloss="1"/>
                <geom type="mesh" contype="0" conaffinity="0" group="1" density="0" mesh="z1_Link05"/>
                <body name="link06" pos="0.0492 0 0">
                  <inertial pos="0.0241569 -0.00017355 -0.00143876" quat="0.998779 0.0457735 -0.00663717 0.0173548" mass="0.288758" diaginertia="0.00018333 0.000147464 0.000146786"/>
                  <joint name="joint6" pos="0 0 0" axis="1 0 0" range="-2.79253 2.79253" damping="1" frictionloss="1"/>
                  <geom type="mesh" contype="0" conaffinity="0" group="1" density="0" mesh="z1_Link06"/>
                  <geom size="0.0325 0.0255" pos="0.0255 0 0" quat="0.707107 0 0.707107 0" type="cylinder"/>
                </body>
              </body>
            </body>
          </body>
        </body>
      </body>
    </body>
  </worldbody>
</mujoco>
